I am process 29462, running on gpu06: starting (Sat Mar  5 11:10:34 2022)
args.batch_size 8
args Namespace(a_imagenet_pretrain=True, a_patch_num=256, audioset_pretrain=False, bal=None, batch_size=8, data_eval='test_iemocap_dataset.json', data_train='train_iemocap_dataset.json', data_val='valid_iemocap_dataset.json', dataset='iemocap', early_stop=5, exp_dir='model_dir/temp_imagenet_8_0.0001_40_fusion', face_size=128, freqm=0, fstride=16, k=-1, label_csv='', lr=0.0001, lr_patience=2, mixup=0, modal='tav', model='ast_models_video_deit_transformer_freeze', n_class=6, n_epochs=40, n_print_steps=100, num_height=384, num_width=384, num_workers=12, optim='adam', save_model=None, scale=0, seed=1234, text_lr_factor=100, text_max_len=300, time_dim_split=True, timem=0, tstride=16, v_imagenet_pretrain=True, v_patch_num=256)
now process iemocap
---------------the train dataloader---------------
number of classes is 6
now process iemocap
---------------the evaluation dataloader---------------
number of classes is 6
---------------AST Model Summary---------------
ImageNet pretraining: True, AudioSet pretraining: False
frequncey stride=16, time stride=16
number of patches=512
---------------AST Model Summary---------------
ImageNet pretraining: True, AudioSet pretraining: False
frequncey stride=16, time stride=16
number of patches=256
Creating experiment directory: model_dir/temp_imagenet_8_0.0001_40_fusion
Some weights of the model checkpoint at /users10/zyzhang/graduationProject/data/pretrain_model/bert_base_uncased were not used when initializing BertModel: ['cls.predictions.transform.dense.bias', 'cls.seq_relationship.weight', 'cls.predictions.transform.LayerNorm.weight', 'cls.predictions.bias', 'cls.seq_relationship.bias', 'cls.predictions.decoder.weight', 'cls.predictions.transform.LayerNorm.bias', 'cls.predictions.transform.dense.weight']
- This IS expected if you are initializing BertModel from the checkpoint of a model trained on another task or with another architecture (e.g. initializing a BertForSequenceClassification model from a BertForPreTraining model).
- This IS NOT expected if you are initializing BertModel from the checkpoint of a model that you expect to be exactly identical (initializing a BertForSequenceClassification model from a BertForSequenceClassification model).
Traceback (most recent call last):
  File "run.py", line 272, in <module>
    os.makedirs("%s/models" % args.exp_dir)
  File "/users10/zyzhang/anaconda3/envs/SparseEnd2End/lib/python3.7/os.py", line 223, in makedirs
    mkdir(name, mode)
FileExistsError: [Errno 17] File exists: 'model_dir/temp_imagenet_8_0.0001_40_fusion/models'